Workbook

Sheet MASTER_DATA
A1: 기본정보 | H1: 진척도(%) | N1: 종합
A2: Team_ID | B2: Region | C2: School_Name | D2: Team_Name | E2: Project_Theme | F2: Last_Updated | G2: Doc_URL | H2: M1_Status | I2: M2_Status | J2: M3_Status | K2: M4_Status | L2: M5_Status | M2: Progress_Total | N2: Risk_Flag | O2: Teacher_Note
A3: T-서울-01-01 | B3: 서울 | C3: 서울 디지털중학교 | D3: AI 패트롤 1팀 | E3: 가스 감지 AI 순찰 로봇 | F3: 2026-04-04 | G3: https://docs.google.com/document/d/dummy_T-서울-01-01 | H3: 53 | I3: 51 | J3: 52 | K3: 18 | L3: 44 | M3: =ROUND(AVERAGE(H3:L3),1) | N3: 위험 | O3: 팀 내 역할 분담 미정, 조율 지원 필요
A4: T-서울-01-02 | B4: 서울 | C4: 서울 디지털중학교 | D4: 해치 2팀 | E4: 시각장애인 안내 AI 반려견 | F4: 2026-04-14 | G4: https://docs.google.com/document/d/dummy_T-서울-01-02 | H4: 48 | I4: 40 | J4: 32 | K4: 23 | L4: 0 | M4: =ROUND(AVERAGE(H4:L4),1) | N4: 주의 | O4: 진도 다소 지연, 이번 주 체크인 예정
A5: T-서울-01-03 | B5: 서울 | C5: 서울 디지털중학교 | D5: 에코봇 3팀 | E5: 학교 쓰레기 분류 자동화 로봇 | F5: 2026-04-06 | G5: https://docs.google.com/document/d/dummy_T-서울-01-03 | H5: 69 | I5: 63 | J5: 51 | K5: 38 | L5: 26 | M5: =ROUND(AVERAGE(H5:L5),1) | N5: 위험 | O5: M2 기능 우선순위표 미완성, 보완 지도 요청
A6: T-서울-01-04 | B6: 서울 | C6: 서울 디지털중학교 | D6: 세이프티 4팀 | E6: 교내 낙상 감지 알림 시스템 | F6: 2026-04-10 | G6: https://docs.google.com/document/d/dummy_T-서울-01-04 | H6: 54 | I6: 57 | J6: 46 | K6: 38 | L6: 17 | M6: =ROUND(AVERAGE(H6:L6),1) | N6: 주의 | O6: M3 진입 예정, 방향성 재확인 권장
A7: T-부산-02-01 | B7: 부산 | C7: 부산 AI창의중학교 | D7: AI 패트롤 1팀 | E7: 가스 감지 AI 순찰 로봇 | F7: 2026-04-03 | G7: https://docs.google.com/document/d/dummy_T-부산-02-01 | H7: 78 | I7: 72 | J7: 58 | K7: 40 | L7: 48 | M7: =ROUND(AVERAGE(H7:L7),1) | N7: 위험 | O7: 7일 이상 미업데이트, 팀 연락 요망
A8: T-부산-02-02 | B8: 부산 | C8: 부산 AI창의중학교 | D8: 해치 2팀 | E8: 시각장애인 안내 AI 반려견 | F8: 2026-04-03 | G8: https://docs.google.com/document/d/dummy_T-부산-02-02 | H8: 44 | I8: 47 | J8: 49 | K8: 44 | L8: 31 | M8: =ROUND(AVERAGE(H8:L8),1) | N8: 위험 | O8: M2 기능 우선순위표 미완성, 보완 지도 요청
A9: T-부산-02-03 | B9: 부산 | C9: 부산 AI창의중학교 | D9: 에코봇 3팀 | E9: 학교 쓰레기 분류 자동화 로봇 | F9: 2026-04-12 | G9: https://docs.google.com/document/d/dummy_T-부산-02-03 | H9: 70 | I9: 59 | J9: 41 | K9: 42 | L9: 25 | M9: =ROUND(AVERAGE(H9:L9),1) | N9: 주의 | O9: M3 진입 예정, 방향성 재확인 권장
A10: T-부산-02-04 | B10: 부산 | C10: 부산 AI창의중학교 | D10: 세이프티 4팀 | E10: 교내 낙상 감지 알림 시스템 | F10: 2026-04-06 | G10: https://docs.google.com/document/d/dummy_T-부산-02-04 | H10: 94 | I10: 83 | J10: 78 | K10: 55 | L10: 72 | M10: =ROUND(AVERAGE(H10:L10),1) | N10: 위험 | O10: M2 기능 우선순위표 미완성, 보완 지도 요청
A11: T-대구-03-01 | B11: 대구 | C11: 대구 미래중학교 | D11: AI 패트롤 1팀 | E11: 가스 감지 AI 순찰 로봇 | F11: 2026-04-01 | G11: https://docs.google.com/document/d/dummy_T-대구-03-01 | H11: 99 | I11: 96 | J11: 69 | K11: 77 | L11: 92 | M11: =ROUND(AVERAGE(H11:L11),1) | N11: 위험 | O11: M2 기능 우선순위표 미완성, 보완 지도 요청
A12: T-대구-03-02 | B12: 대구 | C12: 대구 미래중학교 | D12: 해치 2팀 | E12: 시각장애인 안내 AI 반려견 | F12: 2026-04-11 | G12: https://docs.google.com/document/d/dummy_T-대구-03-02 | H12: 85 | I12: 74 | J12: 83 | K12: 82 | L12: 37 | M12: =ROUND(AVERAGE(H12:L12),1) | N12: 정상
A13: T-대구-03-03 | B13: 대구 | C13: 대구 미래중학교 | D13: 에코봇 3팀 | E13: 학교 쓰레기 분류 자동화 로봇 | F13: 2026-04-06 | G13: https://docs.google.com/document/d/dummy_T-대구-03-03 | H13: 57 | I13: 51 | J13: 49 | K13: 54 | L13: 27 | M13: =ROUND(AVERAGE(H13:L13),1) | N13: 위험 | O13: M3 디버그 로그 미작성 — 개별 면담 필요
A14: T-대구-03-04 | B14: 대구 | C14: 대구 미래중학교 | D14: 세이프티 4팀 | E14: 교내 낙상 감지 알림 시스템 | F14: 2026-04-02 | G14: https://docs.google.com/document/d/dummy_T-대구-03-04 | H14: 51 | I14: 41 | J14: 18 | K14: 25 | L14: 43 | M14: =ROUND(AVERAGE(H14:L14),1) | N14: 위험 | O14: 팀 내 역할 분담 미정, 조율 지원 필요
A15: T-인천-04-01 | B15: 인천 | C15: 인천 스마트중학교 | D15: AI 패트롤 1팀 | E15: 가스 감지 AI 순찰 로봇 | F15: 2026-04-05 | G15: https://docs.google.com/document/d/dummy_T-인천-04-01 | H15: 75 | I15: 71 | J15: 57 | K15: 40 | L15: 27 | M15: =ROUND(AVERAGE(H15:L15),1) | N15: 위험 | O15: M2 기능 우선순위표 미완성, 보완 지도 요청
A16: T-인천-04-02 | B16: 인천 | C16: 인천 스마트중학교 | D16: 해치 2팀 | E16: 시각장애인 안내 AI 반려견 | F16: 2026-04-13 | G16: https://docs.google.com/document/d/dummy_T-인천-04-02 | H16: 66 | I16: 61 | J16: 41 | K16: 42 | L16: 35 | M16: =ROUND(AVERAGE(H16:L16),1) | N16: 주의 | O16: 진도 다소 지연, 이번 주 체크인 예정
A17: T-인천-04-03 | B17: 인천 | C17: 인천 스마트중학교 | D17: 에코봇 3팀 | E17: 학교 쓰레기 분류 자동화 로봇 | F17: 2026-04-10 | G17: https://docs.google.com/document/d/dummy_T-인천-04-03 | H17: 81 | I17: 85 | J17: 77 | K17: 57 | L17: 81 | M17: =ROUND(AVERAGE(H17:L17),1) | N17: 주의 | O17: 센서 선정 단계에서 질문 많음, 추가 안내 예정
A18: T-인천-04-04 | B18: 인천 | C18: 인천 스마트중학교 | D18: 세이프티 4팀 | E18: 교내 낙상 감지 알림 시스템 | F18: 2026-04-07 | G18: https://docs.google.com/document/d/dummy_T-인천-04-04 | H18: 46 | I18: 35 | J18: 44 | K18: 32 | L18: 46 | M18: =ROUND(AVERAGE(H18:L18),1) | N18: 위험 | O18: 팀 내 역할 분담 미정, 조율 지원 필요
A19: T-광주-05-01 | B19: 광주 | C19: 광주 소프트중학교 | D19: AI 패트롤 1팀 | E19: 가스 감지 AI 순찰 로봇 | F19: 2026-04-01 | G19: https://docs.google.com/document/d/dummy_T-광주-05-01 | H19: 46 | I19: 40 | J19: 40 | K19: 24 | L19: 40 | M19: =ROUND(AVERAGE(H19:L19),1) | N19: 위험 | O19: 팀 내 역할 분담 미정, 조율 지원 필요
A20: T-광주-05-02 | B20: 광주 | C20: 광주 소프트중학교 | D20: 해치 2팀 | E20: 시각장애인 안내 AI 반려견 | F20: 2026-04-11 | G20: https://docs.google.com/document/d/dummy_T-광주-05-02 | H20: 81 | I20: 69 | J20: 62 | K20: 49 | L20: 48 | M20: =ROUND(AVERAGE(H20:L20),1) | N20: 정상
A21: T-광주-05-03 | B21: 광주 | C21: 광주 소프트중학교 | D21: 에코봇 3팀 | E21: 학교 쓰레기 분류 자동화 로봇 | F21: 2026-04-07 | G21: https://docs.google.com/document/d/dummy_T-광주-05-03 | H21: 54 | I21: 51 | J21: 48 | K21: 29 | L21: 18 | M21: =ROUND(AVERAGE(H21:L21),1) | N21: 위험 | O21: M3 디버그 로그 미작성 — 개별 면담 필요
A22: T-광주-05-04 | B22: 광주 | C22: 광주 소프트중학교 | D22: 세이프티 4팀 | E22: 교내 낙상 감지 알림 시스템 | F22: 2026-04-13 | G22: https://docs.google.com/document/d/dummy_T-광주-05-04 | H22: 95 | I22: 91 | J22: 89 | K22: 84 | L22: 77 | M22: =ROUND(AVERAGE(H22:L22),1) | N22: 정상
A23: T-대전-06-01 | B23: 대전 | C23: 대전 테크중학교 | D23: AI 패트롤 1팀 | E23: 가스 감지 AI 순찰 로봇 | F23: 2026-04-04 | G23: https://docs.google.com/document/d/dummy_T-대전-06-01 | H23: 73 | I23: 70 | J23: 56 | K23: 64 | L23: 25 | M23: =ROUND(AVERAGE(H23:L23),1) | N23: 위험 | O23: 7일 이상 미업데이트, 팀 연락 요망
A24: T-대전-06-02 | B24: 대전 | C24: 대전 테크중학교 | D24: 해치 2팀 | E24: 시각장애인 안내 AI 반려견 | F24: 2026-04-13 | G24: https://docs.google.com/document/d/dummy_T-대전-06-02 | H24: 50 | I24: 45 | J24: 36 | K24: 22 | L24: 4 | M24: =ROUND(AVERAGE(H24:L24),1) | N24: 주의 | O24: 진도 다소 지연, 이번 주 체크인 예정
A25: T-대전-06-03 | B25: 대전 | C25: 대전 테크중학교 | D25: 에코봇 3팀 | E25: 학교 쓰레기 분류 자동화 로봇 | F25: 2026-04-13 | G25: https://docs.google.com/document/d/dummy_T-대전-06-03 | H25: 48 | I25: 40 | J25: 43 | K25: 36 | L25: 23 | M25: =ROUND(AVERAGE(H25:L25),1) | N25: 주의 | O25: 센서 선정 단계에서 질문 많음, 추가 안내 예정
A26: T-대전-06-04 | B26: 대전 | C26: 대전 테크중학교 | D26: 세이프티 4팀 | E26: 교내 낙상 감지 알림 시스템 | F26: 2026-04-12 | G26: https://docs.google.com/document/d/dummy_T-대전-06-04 | H26: 64 | I26: 59 | J26: 34 | K26: 63 | L26: 19 | M26: =ROUND(AVERAGE(H26:L26),1) | N26: 주의 | O26: M3 진입 예정, 방향성 재확인 권장
A27: T-울산-07-01 | B27: 울산 | C27: 울산 코딩중학교 | D27: AI 패트롤 1팀 | E27: 가스 감지 AI 순찰 로봇 | F27: 2026-04-13 | G27: https://docs.google.com/document/d/dummy_T-울산-07-01 | H27: 96 | I27: 85 | J27: 80 | K27: 80 | L27: 82 | M27: =ROUND(AVERAGE(H27:L27),1) | N27: 정상
A28: T-울산-07-02 | B28: 울산 | C28: 울산 코딩중학교 | D28: 해치 2팀 | E28: 시각장애인 안내 AI 반려견 | F28: 2026-04-14 | G28: https://docs.google.com/document/d/dummy_T-울산-07-02 | H28: 67 | I28: 64 | J28: 44 | K28: 36 | L28: 63 | M28: =ROUND(AVERAGE(H28:L28),1) | N28: 주의 | O28: 센서 선정 단계에서 질문 많음, 추가 안내 예정
A29: T-울산-07-03 | B29: 울산 | C29: 울산 코딩중학교 | D29: 에코봇 3팀 | E29: 학교 쓰레기 분류 자동화 로봇 | F29: 2026-04-11 | G29: https://docs.google.com/document/d/dummy_T-울산-07-03 | H29: 45 | I29: 48 | J29: 52 | K29: 19 | L29: 13 | M29: =ROUND(AVERAGE(H29:L29),1) | N29: 정상
A30: T-울산-07-04 | B30: 울산 | C30: 울산 코딩중학교 | D30: 세이프티 4팀 | E30: 교내 낙상 감지 알림 시스템 | F30: 2026-04-12 | G30: https://docs.google.com/document/d/dummy_T-울산-07-04 | H30: 52 | I30: 50 | J30: 33 | K30: 19 | L30: 28 | M30: =ROUND(AVERAGE(H30:L30),1) | N30: 주의 | O30: 진도 다소 지연, 이번 주 체크인 예정
A31: T-수원-08-01 | B31: 수원 | C31: 수원 데이터중학교 | D31: AI 패트롤 1팀 | E31: 가스 감지 AI 순찰 로봇 | F31: 2026-04-11 | G31: https://docs.google.com/document/d/dummy_T-수원-08-01 | H31: 87 | I31: 77 | J31: 64 | K31: 51 | L31: 50 | M31: =ROUND(AVERAGE(H31:L31),1) | N31: 정상
A32: T-수원-08-02 | B32: 수원 | C32: 수원 데이터중학교 | D32: 해치 2팀 | E32: 시각장애인 안내 AI 반려견 | F32: 2026-03-31 | G32: https://docs.google.com/document/d/dummy_T-수원-08-02 | H32: 56 | I32: 50 | J32: 55 | K32: 46 | L32: 14 | M32: =ROUND(AVERAGE(H32:L32),1) | N32: 위험 | O32: M2 기능 우선순위표 미완성, 보완 지도 요청
A33: T-수원-08-03 | B33: 수원 | C33: 수원 데이터중학교 | D33: 에코봇 3팀 | E33: 학교 쓰레기 분류 자동화 로봇 | F33: 2026-04-07 | G33: https://docs.google.com/document/d/dummy_T-수원-08-03 | H33: 69 | I33: 63 | J33: 42 | K33: 65 | L33: 33 | M33: =ROUND(AVERAGE(H33:L33),1) | N33: 위험 | O33: M2 기능 우선순위표 미완성, 보완 지도 요청
A34: T-수원-08-04 | B34: 수원 | C34: 수원 데이터중학교 | D34: 세이프티 4팀 | E34: 교내 낙상 감지 알림 시스템 | F34: 2026-04-12 | G34: https://docs.google.com/document/d/dummy_T-수원-08-04 | H34: 69 | I34: 63 | J34: 60 | K34: 43 | L34: 24 | M34: =ROUND(AVERAGE(H34:L34),1) | N34: 정상
A35: T-청주-09-01 | B35: 청주 | C35: 청주 로봇중학교 | D35: AI 패트롤 1팀 | E35: 가스 감지 AI 순찰 로봇 | F35: 2026-04-06 | G35: https://docs.google.com/document/d/dummy_T-청주-09-01 | H35: 42 | I35: 36 | J35: 45 | K35: 37 | L35: 36 | M35: =ROUND(AVERAGE(H35:L35),1) | N35: 위험 | O35: 7일 이상 미업데이트, 팀 연락 요망
A36: T-청주-09-02 | B36: 청주 | C36: 청주 로봇중학교 | D36: 해치 2팀 | E36: 시각장애인 안내 AI 반려견 | F36: 2026-04-10 | G36: https://docs.google.com/document/d/dummy_T-청주-09-02 | H36: 65 | I36: 52 | J36: 52 | K36: 34 | L36: 29 | M36: =ROUND(AVERAGE(H36:L36),1) | N36: 주의 | O36: 센서 선정 단계에서 질문 많음, 추가 안내 예정
A37: T-청주-09-03 | B37: 청주 | C37: 청주 로봇중학교 | D37: 에코봇 3팀 | E37: 학교 쓰레기 분류 자동화 로봇 | F37: 2026-03-31 | G37: https://docs.google.com/document/d/dummy_T-청주-09-03 | H37: 43 | I37: 43 | J37: 52 | K37: 36 | L37: 9 | M37: =ROUND(AVERAGE(H37:L37),1) | N37: 위험 | O37: 7일 이상 미업데이트, 팀 연락 요망
A38: T-청주-09-04 | B38: 청주 | C38: 청주 로봇중학교 | D38: 세이프티 4팀 | E38: 교내 낙상 감지 알림 시스템 | F38: 2026-04-03 | G38: https://docs.google.com/document/d/dummy_T-청주-09-04 | H38: 72 | I38: 70 | J38: 74 | K38: 43 | L38: 44 | M38: =ROUND(AVERAGE(H38:L38),1) | N38: 위험 | O38: M2 기능 우선순위표 미완성, 보완 지도 요청
A39: T-전주-10-01 | B39: 전주 | C39: 전주 메이커중학교 | D39: AI 패트롤 1팀 | E39: 가스 감지 AI 순찰 로봇 | F39: 2026-04-05 | G39: https://docs.google.com/document/d/dummy_T-전주-10-01 | H39: 79 | I39: 83 | J39: 71 | K39: 48 | L39: 60 | M39: =ROUND(AVERAGE(H39:L39),1) | N39: 위험 | O39: 7일 이상 미업데이트, 팀 연락 요망
A40: T-전주-10-02 | B40: 전주 | C40: 전주 메이커중학교 | D40: 해치 2팀 | E40: 시각장애인 안내 AI 반려견 | F40: 2026-04-04 | G40: https://docs.google.com/document/d/dummy_T-전주-10-02 | H40: 48 | I40: 41 | J40: 31 | K40: 44 | L40: 4 | M40: =ROUND(AVERAGE(H40:L40),1) | N40: 위험 | O40: 팀 내 역할 분담 미정, 조율 지원 필요
...

Sheet 진척도_요약
A1: 지역 | B1: 학교명 | C1: 팀수 | D1: M1_avg | E1: M2_avg | F1: M3_avg | G1: M4_avg | H1: M5_avg | I1: 전체진척도_avg | J1: 위험팀 | K1: 주의팀 | L1: 정상팀
A2: 서울 | B2: 서울 디지털중학교 | C2: 4 | D2: =ROUND(AVERAGE(MASTER_DATA!H3:H6),1) | E2: =ROUND(AVERAGE(MASTER_DATA!I3:I6),1) | F2: =ROUND(AVERAGE(MASTER_DATA!J3:J6),1) | G2: =ROUND(AVERAGE(MASTER_DATA!K3:K6),1) | H2: =ROUND(AVERAGE(MASTER_DATA!L3:L6),1) | I2: =ROUND(AVERAGE(MASTER_DATA!M3:M6),1) | J2: =COUNTIF(MASTER_DATA!N3:N6,"위험") | K2: =COUNTIF(MASTER_DATA!N3:N6,"주의") | L2: =COUNTIF(MASTER_DATA!N3:N6,"정상")
A3: 부산 | B3: 부산 AI창의중학교 | C3: 4 | D3: =ROUND(AVERAGE(MASTER_DATA!H7:H10),1) | E3: =ROUND(AVERAGE(MASTER_DATA!I7:I10),1) | F3: =ROUND(AVERAGE(MASTER_DATA!J7:J10),1) | G3: =ROUND(AVERAGE(MASTER_DATA!K7:K10),1) | H3: =ROUND(AVERAGE(MASTER_DATA!L7:L10),1) | I3: =ROUND(AVERAGE(MASTER_DATA!M7:M10),1) | J3: =COUNTIF(MASTER_DATA!N7:N10,"위험") | K3: =COUNTIF(MASTER_DATA!N7:N10,"주의") | L3: =COUNTIF(MASTER_DATA!N7:N10,"정상")
A4: 대구 | B4: 대구 미래중학교 | C4: 4 | D4: =ROUND(AVERAGE(MASTER_DATA!H11:H14),1) | E4: =ROUND(AVERAGE(MASTER_DATA!I11:I14),1) | F4: =ROUND(AVERAGE(MASTER_DATA!J11:J14),1) | G4: =ROUND(AVERAGE(MASTER_DATA!K11:K14),1) | H4: =ROUND(AVERAGE(MASTER_DATA!L11:L14),1) | I4: =ROUND(AVERAGE(MASTER_DATA!M11:M14),1) | J4: =COUNTIF(MASTER_DATA!N11:N14,"위험") | K4: =COUNTIF(MASTER_DATA!N11:N14,"주의") | L4: =COUNTIF(MASTER_DATA!N11:N14,"정상")
A5: 인천 | B5: 인천 스마트중학교 | C5: 4 | D5: =ROUND(AVERAGE(MASTER_DATA!H15:H18),1) | E5: =ROUND(AVERAGE(MASTER_DATA!I15:I18),1) | F5: =ROUND(AVERAGE(MASTER_DATA!J15:J18),1) | G5: =ROUND(AVERAGE(MASTER_DATA!K15:K18),1) | H5: =ROUND(AVERAGE(MASTER_DATA!L15:L18),1) | I5: =ROUND(AVERAGE(MASTER_DATA!M15:M18),1) | J5: =COUNTIF(MASTER_DATA!N15:N18,"위험") | K5: =COUNTIF(MASTER_DATA!N15:N18,"주의") | L5: =COUNTIF(MASTER_DATA!N15:N18,"정상")
A6: 광주 | B6: 광주 소프트중학교 | C6: 4 | D6: =ROUND(AVERAGE(MASTER_DATA!H19:H22),1) | E6: =ROUND(AVERAGE(MASTER_DATA!I19:I22),1) | F6: =ROUND(AVERAGE(MASTER_DATA!J19:J22),1) | G6: =ROUND(AVERAGE(MASTER_DATA!K19:K22),1) | H6: =ROUND(AVERAGE(MASTER_DATA!L19:L22),1) | I6: =ROUND(AVERAGE(MASTER_DATA!M19:M22),1) | J6: =COUNTIF(MASTER_DATA!N19:N22,"위험") | K6: =COUNTIF(MASTER_DATA!N19:N22,"주의") | L6: =COUNTIF(MASTER_DATA!N19:N22,"정상")
A7: 대전 | B7: 대전 테크중학교 | C7: 4 | D7: =ROUND(AVERAGE(MASTER_DATA!H23:H26),1) | E7: =ROUND(AVERAGE(MASTER_DATA!I23:I26),1) | F7: =ROUND(AVERAGE(MASTER_DATA!J23:J26),1) | G7: =ROUND(AVERAGE(MASTER_DATA!K23:K26),1) | H7: =ROUND(AVERAGE(MASTER_DATA!L23:L26),1) | I7: =ROUND(AVERAGE(MASTER_DATA!M23:M26),1) | J7: =COUNTIF(MASTER_DATA!N23:N26,"위험") | K7: =COUNTIF(MASTER_DATA!N23:N26,"주의") | L7: =COUNTIF(MASTER_DATA!N23:N26,"정상")
A8: 울산 | B8: 울산 코딩중학교 | C8: 4 | D8: =ROUND(AVERAGE(MASTER_DATA!H27:H30),1) | E8: =ROUND(AVERAGE(MASTER_DATA!I27:I30),1) | F8: =ROUND(AVERAGE(MASTER_DATA!J27:J30),1) | G8: =ROUND(AVERAGE(MASTER_DATA!K27:K30),1) | H8: =ROUND(AVERAGE(MASTER_DATA!L27:L30),1) | I8: =ROUND(AVERAGE(MASTER_DATA!M27:M30),1) | J8: =COUNTIF(MASTER_DATA!N27:N30,"위험") | K8: =COUNTIF(MASTER_DATA!N27:N30,"주의") | L8: =COUNTIF(MASTER_DATA!N27:N30,"정상")
A9: 수원 | B9: 수원 데이터중학교 | C9: 4 | D9: =ROUND(AVERAGE(MASTER_DATA!H31:H34),1) | E9: =ROUND(AVERAGE(MASTER_DATA!I31:I34),1) | F9: =ROUND(AVERAGE(MASTER_DATA!J31:J34),1) | G9: =ROUND(AVERAGE(MASTER_DATA!K31:K34),1) | H9: =ROUND(AVERAGE(MASTER_DATA!L31:L34),1) | I9: =ROUND(AVERAGE(MASTER_DATA!M31:M34),1) | J9: =COUNTIF(MASTER_DATA!N31:N34,"위험") | K9: =COUNTIF(MASTER_DATA!N31:N34,"주의") | L9: =COUNTIF(MASTER_DATA!N31:N34,"정상")
A10: 청주 | B10: 청주 로봇중학교 | C10: 4 | D10: =ROUND(AVERAGE(MASTER_DATA!H35:H38),1) | E10: =ROUND(AVERAGE(MASTER_DATA!I35:I38),1) | F10: =ROUND(AVERAGE(MASTER_DATA!J35:J38),1) | G10: =ROUND(AVERAGE(MASTER_DATA!K35:K38),1) | H10: =ROUND(AVERAGE(MASTER_DATA!L35:L38),1) | I10: =ROUND(AVERAGE(MASTER_DATA!M35:M38),1) | J10: =COUNTIF(MASTER_DATA!N35:N38,"위험") | K10: =COUNTIF(MASTER_DATA!N35:N38,"주의") | L10: =COUNTIF(MASTER_DATA!N35:N38,"정상")
A11: 전주 | B11: 전주 메이커중학교 | C11: 4 | D11: =ROUND(AVERAGE(MASTER_DATA!H39:H42),1) | E11: =ROUND(AVERAGE(MASTER_DATA!I39:I42),1) | F11: =ROUND(AVERAGE(MASTER_DATA!J39:J42),1) | G11: =ROUND(AVERAGE(MASTER_DATA!K39:K42),1) | H11: =ROUND(AVERAGE(MASTER_DATA!L39:L42),1) | I11: =ROUND(AVERAGE(MASTER_DATA!M39:M42),1) | J11: =COUNTIF(MASTER_DATA!N39:N42,"위험") | K11: =COUNTIF(MASTER_DATA!N39:N42,"주의") | L11: =COUNTIF(MASTER_DATA!N39:N42,"정상")
A12: 전체 | B12: 합계/평균 | C12: =SUM(C2:C11) | D12: =ROUND(AVERAGE(D2:D11),1) | E12: =ROUND(AVERAGE(E2:E11),1) | F12: =ROUND(AVERAGE(F2:F11),1) | G12: =ROUND(AVERAGE(G2:G11),1) | H12: =ROUND(AVERAGE(H2:H11),1) | I12: =ROUND(AVERAGE(I2:I11),1) | J12: =SUM(J2:J11) | K12: =SUM(K2:K11) | L12: =SUM(L2:L11)
